Workbook

Sheet 2026-27 A.Y. I Sem
A1: 2026-27 A.Y. I Sem B.Tech Nominal Rolls
A2: S.No. | B2: S.No. | C2: Yr/Sem. | D2: Department | E2: Section | F2: Yr/Br/Sc | G2: Roll Number | H2: Student Name | I2: Father Name | J2: Mother Name | K2: Gender | L2: Student Mobile.No | M2: Parent Mobile.No | N2: Aadhaar No. | O2: email ID
A3: =ROW()-ROW($A$2) -> 1 | B3: =ROW()-ROW($A$2) -> 1 | C3: IV-I | D3: ECE | E3: A | F3: =CONCATENATE(C3," ",D3,"-",E3) -> IV-I ECE-A | G3: 22VE1A0441 | H3: NANDIKONDA SRI CHARAN REDDY | I3: NANDIKONDA SRINIVAS REDDY | K3: Male | L3: 8520985630 | M3: 8520985630 | N3: 591964569065 | O3: charanreddy4682@gmail.com
A4: =ROW()-ROW($A$2) -> 2 | B4: =ROW()-ROW($A$2) -> 2 | C4: IV-I | D4: ECE | E4: A | F4: =CONCATENATE(C4," ",D4,"-",E4) -> IV-I ECE-A | G4: 23VE1A0401 | H4: ADEPU SHIVAMANI | I4: ADEPU BHAVANARUSHI | J4: ADEPU KAVITHA | K4: Male | L4: 9347569003 | M4: 9553246503 | N4: 323383968153 | O4: shivamaniadepu@gmail.com
A5: =ROW()-ROW($A$2) -> 3 | B5: =ROW()-ROW($A$2) -> 3 | C5: IV-I | D5: ECE | E5: A | F5: =CONCATENATE(C5," ",D5,"-",E5) -> IV-I ECE-A | G5: 23VE1A0402 | H5: AKARAPU VENNELA | I5: AKARAPU VENKANNA | J5: AKARAPU NAGAMMA | K5: Female | L5: 7386452106 | M5: 8074190985 | N5: 560346024361 | O5: akarapuvennela06@gmail.com
A6: =ROW()-ROW($A$2) -> 4 | B6: =ROW()-ROW($A$2) -> 4 | C6: IV-I | D6: ECE | E6: A | F6: =CONCATENATE(C6," ",D6,"-",E6) -> IV-I ECE-A | G6: 23VE1A0403 | H6: BADAM NAVEEN KUMAR REDDY | I6: BADAM BALA KRISHNA REDDY | J6: BADAM MALLESWARI | K6: Male | L6: 9959162064 | M6: 9705442685 | N6: 522812147240 | O6: badamnaveenkumarreddy@gmail.com
A7: =ROW()-ROW($A$2) -> 5 | B7: =ROW()-ROW($A$2) -> 5 | C7: IV-I | D7: ECE | E7: A | F7: =CONCATENATE(C7," ",D7,"-",E7) -> IV-I ECE-A | G7: 23VE1A0404 | H7: BALAGONI VAISHNAVI | I7: BALAGONI SATYANARAYANA GOUD | J7: BALAGONI NAGAMANI | K7: Female | L7: 6281300408 | M7: 9966308420 | N7: 497645323713 | O7: vaishubalagoni@gmail.com
A8: =ROW()-ROW($A$2) -> 6 | B8: =ROW()-ROW($A$2) -> 6 | C8: IV-I | D8: ECE | E8: A | F8: =CONCATENATE(C8," ",D8,"-",E8) -> IV-I ECE-A | G8: 23VE1A0405 | H8: BATHALA SHASHANK SHREEVATHSAV | I8: BATHALA SUBBARAYUDU | J8: BATHALA LAKSHMI KALA | K8: Male | L8: 6304957156 | M8: 9849716240 | N8: 433340610978 | O8: shashanksreevathsav@gmail.com
A9: =ROW()-ROW($A$2) -> 7 | B9: =ROW()-ROW($A$2) -> 7 | C9: IV-I | D9: ECE | E9: A | F9: =CONCATENATE(C9," ",D9,"-",E9) -> IV-I ECE-A | G9: 23VE1A0406 | H9: BEEMAGANI RANADEEP | I9: BEEMAGANI SRINIVAS | J9: BEEMAGANI RENUKA | K9: Male | L9: 6302491074 | M9: 7672093862 | N9: 461593411121 | O9: ranadeepranadeep93@gmail.com
A10: =ROW()-ROW($A$2) -> 8 | B10: =ROW()-ROW($A$2) -> 8 | C10: IV-I | D10: ECE | E10: A | F10: =CONCATENATE(C10," ",D10,"-",E10) -> IV-I ECE-A | G10: 23VE1A0407 | H10: BHIMIREDDY DHRUVA REDDY | I10: BHIMIREDDY LAKSHMA REDDY | J10: ALLA PREMA SAI | K10: Male | L10: 8341459860 | M10: 8341119860 | N10: 8933-2149-8455 | O10: premaalla@gmail.com
A11: =ROW()-ROW($A$2) -> 9 | B11: =ROW()-ROW($A$2) -> 9 | C11: IV-I | D11: ECE | E11: A | F11: =CONCATENATE(C11," ",D11,"-",E11) -> IV-I ECE-A | G11: 23VE1A0408 | H11: CHANDRAGIRI JAI RISHI CHANDRA | I11: CHANDRA GIRI RAVI CHANDER | J11: K SATYA SRILAXMI | K11: Male | L11: 6300515210 | M11: 9666477788 | N11: 891859912535 | O11: jaic425@gmail.com
A12: =ROW()-ROW($A$2) -> 10 | B12: =ROW()-ROW($A$2) -> 10 | C12: IV-I | D12: ECE | E12: A | F12: =CONCATENATE(C12," ",D12,"-",E12) -> IV-I ECE-A | G12: 23VE1A0409 | H12: CHIMMULA SAI PRAKASH REDDY | I12: CHIMMULA SRINIVAS REDDY | J12: CHIMMULA NIRMALA | K12: Male | L12: 9398829765 | M12: 9848242351 | N12: 355746300248 | O12: saiprakashreddychimmula@gmail.com
A13: =ROW()-ROW($A$2) -> 11 | B13: =ROW()-ROW($A$2) -> 11 | C13: IV-I | D13: ECE | E13: A | F13: =CONCATENATE(C13," ",D13,"-",E13) -> IV-I ECE-A | G13: 23VE1A0410 | H13: CHINTHALA HARIKESH REDDY | I13: CHINTHALA RAMESH REDDY | J13: CHINTHALA SARITHA | K13: Male | L13: 7842842616 | M13: 8328536223 | N13: 294290360496 | O13: chharikeshreddy@gmail.com
A14: =ROW()-ROW($A$2) -> 12 | B14: =ROW()-ROW($A$2) -> 12 | C14: IV-I | D14: ECE | E14: A | F14: =CONCATENATE(C14," ",D14,"-",E14) -> IV-I ECE-A | G14: 23VE1A0411 | H14: CILAVENI NIKIT SAI | I14: CILAVENI SRINIVAS | J14: CILAVENI PADMA | K14: Male | L14: 8555803893 | M14: 9618026175 | N14: 545104930998 | O14: cilaveninikitsai@gmail.com
A15: =ROW()-ROW($A$2) -> 13 | B15: =ROW()-ROW($A$2) -> 13 | C15: IV-I | D15: ECE | E15: A | F15: =CONCATENATE(C15," ",D15,"-",E15) -> IV-I ECE-A | G15: 23VE1A0412 | H15: DARAPUREDDY VENKATA SATYA PRANEETH | I15: D YOGI PRASAD | J15: D BANNIKESWARI | K15: Male | L15: 9390632117 | M15: 9000237125 | N15: 853389467637 | O15: Praneeth5642@gmail.com
A16: =ROW()-ROW($A$2) -> 14 | B16: =ROW()-ROW($A$2) -> 14 | C16: IV-I | D16: ECE | E16: A | F16: =CONCATENATE(C16," ",D16,"-",E16) -> IV-I ECE-A | G16: 23VE1A0413 | H16: DASARI NIKHIL KUMAR | I16: DASARI SOMAIAH | J16: DASARI YADAMMA | K16: Male | L16: 9010304030 | M16: 9985825029 | N16: 668488062358 | O16: d.nikhilkumar44@gmail.com
A17: =ROW()-ROW($A$2) -> 15 | B17: =ROW()-ROW($A$2) -> 15 | C17: IV-I | D17: ECE | E17: A | F17: =CONCATENATE(C17," ",D17,"-",E17) -> IV-I ECE-A | G17: 23VE1A0414 | H17: DONTHARA BOINA CHINMAI | I17: DONTHARA BOINA NARAYANA | J17: DONTHARA BOINA NAGAMANI | K17: Female | L17: 7386315609 | M17: 9490536168 | N17: 848631953925 | O17: chinmaidontharaboina@gmail.com
A18: =ROW()-ROW($A$2) -> 16 | B18: =ROW()-ROW($A$2) -> 16 | C18: IV-I | D18: ECE | E18: A | F18: =CONCATENATE(C18," ",D18,"-",E18) -> IV-I ECE-A | G18: 23VE1A0415 | H18: GONE BHANU CHARAN | I18: GONE SANDEEP KUMAR | J18: GONE KRANTHI | K18: Male | L18: 8374539678 | M18: 9949910023 | N18: 358455137285 | O18: gonebhanucharan9@gmail.com
A19: =ROW()-ROW($A$2) -> 17 | B19: =ROW()-ROW($A$2) -> 17 | C19: IV-I | D19: ECE | E19: A | F19: =CONCATENATE(C19," ",D19,"-",E19) -> IV-I ECE-A | G19: 23VE1A0416 | H19: GUGULOTH GANESH | I19: GUGULOTH RAMESH | J19: GUGULOTH CHILAKAMMA | K19: Male | L19: 9391088354 | M19: 9100597275 | N19: 440087464406 | O19: ggugulothu789@gmail.com
A20: =ROW()-ROW($A$2) -> 18 | B20: =ROW()-ROW($A$2) -> 18 | C20: IV-I | D20: ECE | E20: A | F20: =CONCATENATE(C20," ",D20,"-",E20) -> IV-I ECE-A | G20: 23VE1A0417 | H20: GUNTAPALLI KAVYA SREE | I20: GUNTAPALLI SEKHAR | J20: GUNTAPALLI MADHAVI | K20: Female | L20: 7989719982 | M20: 7569352241 | N20: 867751357425 | O20: kavyasreeguntapalli@gmail.com
A21: =ROW()-ROW($A$2) -> 19 | B21: =ROW()-ROW($A$2) -> 19 | C21: IV-I | D21: ECE | E21: A | F21: =CONCATENATE(C21," ",D21,"-",E21) -> IV-I ECE-A | G21: 23VE1A0418 | H21: INAVOLU SAHITHI REDDY | I21: INAVOLU PANDURANGA REDDY | J21: INAVOLU SWAPNA | K21: Female | L21: 9391585277 | M21: 9347766124 | N21: 515541028200 | O21: sahithireddysahithireddy43@gmail.com
A22: =ROW()-ROW($A$2) -> 20 | B22: =ROW()-ROW($A$2) -> 20 | C22: IV-I | D22: ECE | E22: A | F22: =CONCATENATE(C22," ",D22,"-",E22) -> IV-I ECE-A | G22: 23VE1A0419 | H22: JALDA DAMAYANTHI | I22: JALDA SHANKAR | J22: JALDA LAVANYA | K22: Female | L22: 9618709179 | M22: 9493313212 | N22: 657256213448 | O22: damayanthijalda@gmail.com
... A69: =ROW()-ROW($A$2) -> 67 | B69: =ROW()-ROW($A$2) -> 67 | C69: IV-I | D69: ECE | E69: A | F69: =CONCATENATE(C69," ",D69,"-",E69) -> IV-I ECE-A | G69: 24VE5A0405 | H69: MIRYALA VARSHITHA | I69: MIRYALA SHYAM PRASAD | J69: MIRYALA SARITHA | K69: Female | L69: 7993901201 | M69: 9603948678 | N69: 548360873764 | O69: miryalavarshitha123@gmail.com
A70: =ROW()-ROW($A$2) -> 68 | B70: =ROW()-ROW($A$2) -> 68 | C70: IV-I | D70: ECE | E70: A | F70: =CONCATENATE(C70," ",D70,"-",E70) -> IV-I ECE-A | G70: 24VE5A0406 | H70: MOKHEDE VAISHANAVI | I70: NAMDEV | J70: MEGHA | K70: Female | L70: 9502302711 | N70: 682238519476 | O70: 24VE5A0406@gmail.com
A71: =ROW()-ROW($A$2) -> 69 | B71: =ROW()-ROW($A$2) -> 69 | C71: IV-I | D71: ECE | E71: A | F71: =CONCATENATE(C71," ",D71,"-",E71) -> IV-I ECE-A | G71: 24VE5A0407 | H71: SANJA RAJU | I71: SANJA KONDAIAH | J71: SANJA KANTHAMMA | K71: Male | L71: 9347973911 | M71: 7997069705 | N71: 522461906570 | O71: rajusanja12@gmail.com
A72: =ROW()-ROW($A$2) -> 70 | B72: =ROW()-ROW($A$2) -> 70 | C72: IV-I | D72: ECE | E72: B | F72: =CONCATENATE(C72," ",D72,"-",E72) -> IV-I ECE-B | G72: 23VE1A0465 | H72: AAVULA SUMANTH | I72: AAVULA VENKANNA | J72: AAVULA MANJULA | K72: Male | L72: 6305621837 | M72: 7660814964 | N72: 733304768843 | O72: aavulasumanth90@gmail.com
A73: =ROW()-ROW($A$2) -> 71 | B73: =ROW()-ROW($A$2) -> 71 | C73: IV-I | D73: ECE | E73: B | F73: =CONCATENATE(C73," ",D73,"-",E73) -> IV-I ECE-B | G73: 23VE1A0466 | H73: ABDUL MAJEED AHMED | I73: AIJAZ AHMED | J73: YASMEEN SULTANA | K73: Male | L73: 8885221653 | M73: 9908914237 | N73: 864674187016 | O73: amahmed4002@gmail.com
A74: =ROW()-ROW($A$2) -> 72 | B74: =ROW()-ROW($A$2) -> 72 | C74: IV-I | D74: ECE | E74: B | F74: =CONCATENATE(C74," ",D74,"-",E74) -> IV-I ECE-B | G74: 23VE1A0467 | H74: ALLIKANTI SREEVARSHITH | I74: ALLIKANTI VENKATAIAH | J74: ALLIKANTI INDIRA | K74: Male | L74: 9392798445 | M74: 9948157342 | N74: 210851541721 | O74: sreevarshith78@gmail.com
A75: =ROW()-ROW($A$2) -> 73 | B75: =ROW()-ROW($A$2) -> 73 | C75: IV-I | D75: ECE | E75: B | F75: =CONCATENATE(C75," ",D75,"-",E75) -> IV-I ECE-B | G75: 23VE1A0468 | H75: ATMAKUR RAJVEER SINGH | I75: ATMAKUR SREEKANT KUMAR SINGH | J75: ATMAKUR MAMTA SINGH | K75: Male | L75: 7995762220 | M75: 9963906763 | N75: 464392995029 | O75: rajveersinghatmakur@gmail.com
A76: =ROW()-ROW($A$2) -> 74 | B76: =ROW()-ROW($A$2) -> 74 | C76: IV-I | D76: ECE | E76: B | F76: =CONCATENATE(C76," ",D76,"-",E76) -> IV-I ECE-B | G76: 23VE1A0469 | H76: BADDAM KIRTHI REDDY | I76: BADDAM VENKAT REDDY | J76: BADDAM RANI | K76: Female | L76: 8328084976 | M76: 9866823227 | N76: 673325405055 | O76: bkirthir@gmail.com
A77: =ROW()-ROW($A$2) -> 75 | B77: =ROW()-ROW($A$2) -> 75 | C77: IV-I | D77: ECE | E77: B | F77: =CONCATENATE(C77," ",D77,"-",E77) -> IV-I ECE-B | G77: 23VE1A0472 | H77: BATTU VISHNUVARDHAN YADAV | I77: B SREENIVAS YADAV LATE | J77: B SARASWATHI | K77: Male | L77: 9063674224 | M77: 9603318116 | N77: 781056697049 | O77: vy006406@gmail.com
A78: =ROW()-ROW($A$2) -> 76 | B78: =ROW()-ROW($A$2) -> 76 | C78: IV-I | D78: ECE | E78: B | F78: =CONCATENATE(C78," ",D78,"-",E78) -> IV-I ECE-B | G78: 23VE1A0473 | H78: BETHI MOUNESH | I78: SURESH | J78: PADMA | K78: Male | L78: 6301163124 | M78: 6301163124 | N78: 829218091847 | O78: mounesh041@gmail.com
A79: =ROW()-ROW($A$2) -> 77 | B79: =ROW()-ROW($A$2) -> 77 | C79: IV-I | D79: ECE | E79: B | F79: =CONCATENATE(C79," ",D79,"-",E79) -> IV-I ECE-B | G79: 23VE1A0474 | H79: BISWAL BRUNDHAVAN | I79: BISWAL VIJAY | J79: BISWAL VASANTHI | K79: Male | L79: 9666939454 | M79: 6303090238 | N79: 601189397569 | O79: saikiranbiswal77@gmail.com
A80: =ROW()-ROW($A$2) -> 78 | B80: =ROW()-ROW($A$2) -> 78 | C80: IV-I | D80: ECE | E80: B | F80: =CONCATENATE(C80," ",D80,"-",E80) -> IV-I ECE-B | G80: 23VE1A0475 | H80: CHEPURI AKSHAYA | I80: CHEPURI PARAMESH | J80: CHEPURI UMAVATHI | K80: Female | L80: 9391098189 | M80: 9948064638 | N80: 456174223426 | O80: chepuriparamesh9@gmail.com
A81: =ROW()-ROW($A$2) -> 79 | B81: =ROW()-ROW($A$2) -> 79 | C81: IV-I | D81: ECE | E81: B | F81: =CONCATENATE(C81," ",D81,"-",E81) -> IV-I ECE-B | G81: 23VE1A0476 | H81: CHETTI CHARITHA | I81: CHETTI RAJU | J81: CH LAVANYA | K81: Female | L81: 9550930372 | M81: 9177731344 | N81: 292540213543 | O81: chetticharitha@gmail.com
A82: =ROW()-ROW($A$2) -> 80 | B82: =ROW()-ROW($A$2) -> 80 | C82: IV-I | D82: ECE | E82: B | F82: =CONCATENATE(C82," ",D82,"-",E82) -> IV-I ECE-B | G82: 23VE1A0477 | H82: CHILUMULA CHARAN | I82: CHILUMULA VIJAY PAL | J82: CHILUMULA RAMANA | K82: Male | L82: 6281010170 | M82: 9542536412 | N82: 534702349724 | O82: charanchilumula24@gmail.com
... A101: =ROW()-ROW($A$2) -> 99 | B101: =ROW()-ROW($A$2) -> 99 | C101: IV-I | D101: ECE | E101: B | F101: =CONCATENATE(C101," ",D101,"-",E101) -> IV-I ECE-B | G101: 23VE1A04A3 | H101: MALOTH VENKATESH | I101: MALOTH NAGESWARRAO | J101: MELOTH BHADRAMMA | K101: Male | L101: 6301935399 | M101: 9848851261 | N101: 268005494410 | O101: malothvenky6@gmail.com
A102: =ROW()-ROW($A$2) -> 100 | B102: =ROW()-ROW($A$2) -> 100 | C102: IV-I | D102: ECE | E102: B | F102: =CONCATENATE(C102," ",D102,"-",E102) -> IV-I ECE-B | G102: 23VE1A04A4 | H102: MEGAVATH SATHISH | I102: MEGAVATH ALA | J102: MEGAVATH VIJAYA | K102: Male | L102: 7601061038 | M102: 9347215406 | N102: 7390-7604-5288 | O102: megavathsathish22@gamil.com
A103: =ROW()-ROW($A$2) -> 101 | B103: =ROW()-ROW($A$2) -> 101 | C103: IV-I | D103: ECE | E103: B | F103: =CONCATENATE(C103," ",D103,"-",E103) -> IV-I ECE-B | G103: 23VE1A04A5 | H103: MEGHANA JOSEPH | I103: JOSEPH PIUS FERNANDEZ | J103: JISHA JOSEPH | K103: Female | L103: 8500040844 | M103: 9885662758 | N103: 513869143458 | O103: meghanafernandez@gmail.com
A104: =ROW()-ROW($A$2) -> 102 | B104: =ROW()-ROW($A$2) -> 102 | C104: IV-I | D104: ECE | E104: B | F104: =CONCATENATE(C104," ",D104,"-",E104) -> IV-I ECE-B | G104: 23VE1A04A6 | H104: MEKALA NIKHIL YADAV | I104: MEKALA MAHESH YADAV | J104: MEKALA HEMALATHA YADAV | K104: Male | L104: 9182467248 | M104: 9848111886 | N104: 677121715838 | O104: mekalanikhilyadav69@gmail.com
...

Sheet Count
A1: 2026-27 A.Y_I Semester_B.Tech_College Strength
A2: I-I | C2: II-I | E2: III-I | G2: IV-I | J2: Re-admissions (+) | P2: Removed ( - )
A3: I-I ECE-A | B3: =IF(COUNTIF('2026-27 A.Y. I Sem'!F:F,A3)=0,"0",COUNTIF('2026-27 A.Y. I Sem'!F:F,A3)) -> 0 | C3: II-I ECE-A | D3: =IF(COUNTIF('2026-27 A.Y. I Sem'!F:F,C3)=0,"0",COUNTIF('2026-27 A.Y. I Sem'!F:F,C3)) -> 62 | E3: III-I ECE-A | F3: =IF(COUNTIF('2026-27 A.Y. I Sem'!F:F,E3)=0,"0",COUNTIF('2026-27 A.Y. I Sem'!F:F,E3)) -> 69 | G3: IV-I ECE-A | H3: =IF(COUNTIF('2026-27 A.Y. I Sem'!F:F,G3)=0,"0",COUNTIF('2026-27 A.Y. I Sem'!F:F,G3)) -> 69 | J3: sno. | K3: Hallticket no. | L3: Name | M3: yr/Br/Sec | N3: Circular No. | P3: sno | Q3: Section | R3: Hall Ticket No. | S3: Name | T3: Remarks
A4: I-I CSE-A | B4: =IF(COUNTIF('2026-27 A.Y. I Sem'!F:F,A4)=0,"0",COUNTIF('2026-27 A.Y. I Sem'!F:F,A4)) -> 0 | C4: II-I CSE-A | D4: =IF(COUNTIF('2026-27 A.Y. I Sem'!F:F,C4)=0,"0",COUNTIF('2026-27 A.Y. I Sem'!F:F,C4)) -> 68 | E4: III-I CSE-A | F4: =IF(COUNTIF('2026-27 A.Y. I Sem'!F:F,E4)=0,"0",COUNTIF('2026-27 A.Y. I Sem'!F:F,E4)) -> 60 | G4: IV-I ECE-B | H4: =IF(COUNTIF('2026-27 A.Y. I Sem'!F:F,G4)=0,"0",COUNTIF('2026-27 A.Y. I Sem'!F:F,G4)) -> 59 | J4: =ROW()-ROW($K$3) -> 1 | P4: 1 | Q4: III-II ECE-B | R4: 23VE1A04A2 | S4: MALLEBOINA BALU | T4: III-II Attendance Detain
A5: I-I CSE-B | B5: =IF(COUNTIF('2026-27 A.Y. I Sem'!F:F,A5)=0,"0",COUNTIF('2026-27 A.Y. I Sem'!F:F,A5)) -> 0 | C5: II-I CSE-B | D5: =IF(COUNTIF('2026-27 A.Y. I Sem'!F:F,C5)=0,"0",COUNTIF('2026-27 A.Y. I Sem'!F:F,C5)) -> 68 | E5: III-I CSE-B | F5: =IF(COUNTIF('2026-27 A.Y. I Sem'!F:F,E5)=0,"0",COUNTIF('2026-27 A.Y. I Sem'!F:F,E5)) -> 57 | G5: IV-I CSE-A | H5: =IF(COUNTIF('2026-27 A.Y. I Sem'!F:F,G5)=0,"0",COUNTIF('2026-27 A.Y. I Sem'!F:F,G5)) -> 71 | J5: =ROW()-ROW($K$3) -> 2 | P5: 2 | Q5: III-II ECE-B | R5: 23VE1A04C1 | S5: SHAGA RITHVAK KURUMA | T5: III-II Attendance Detain
A6: I-I CSE-C | B6: =IF(COUNTIF('2026-27 A.Y. I Sem'!F:F,A6)=0,"0",COUNTIF('2026-27 A.Y. I Sem'!F:F,A6)) -> 0 | C6: II-I CSE-C | D6: =IF(COUNTIF('2026-27 A.Y. I Sem'!F:F,C6)=0,"0",COUNTIF('2026-27 A.Y. I Sem'!F:F,C6)) -> 67 | E6: III-I CSE-C | F6: =IF(COUNTIF('2026-27 A.Y. I Sem'!F:F,E6)=0,"0",COUNTIF('2026-27 A.Y. I Sem'!F:F,E6)) -> 60 | G6: IV-I CSE-B | H6: =IF(COUNTIF('2026-27 A.Y. I Sem'!F:F,G6)=0,"0",COUNTIF('2026-27 A.Y. I Sem'!F:F,G6)) -> 67 | J6: =ROW()-ROW($K$3) -> 3 | P6: 3 | Q6: III-II AIML-B | R6: 23VE1A66B3 | S6: REDDEBOINA SAI KRISHNA | T6: III-II Attendance Detain
A7: I-I CSE-D | B7: =IF(COUNTIF('2026-27 A.Y. I Sem'!F:F,A7)=0,"0",COUNTIF('2026-27 A.Y. I Sem'!F:F,A7)) -> 0 | C7: II-I CSE-D | D7: =IF(COUNTIF('2026-27 A.Y. I Sem'!F:F,C7)=0,"0",COUNTIF('2026-27 A.Y. I Sem'!F:F,C7)) -> 69 | E7: III-I CSE-D | F7: =IF(COUNTIF('2026-27 A.Y. I Sem'!F:F,E7)=0,"0",COUNTIF('2026-27 A.Y. I Sem'!F:F,E7)) -> 62 | G7: IV-I CSE-C | H7: =IF(COUNTIF('2026-27 A.Y. I Sem'!F:F,G7)=0,"0",COUNTIF('2026-27 A.Y. I Sem'!F:F,G7)) -> 67 | J7: =ROW()-ROW($K$3) -> 4 | P7: 4 | Q7: II-II CSE-A | R7: 24VE1A0524 | S7: BODDUPALLY THARUN | T7: II-II Attendance Detain
A8: I-I CSE-E | B8: =IF(COUNTIF('2026-27 A.Y. I Sem'!F:F,A8)=0,"0",COUNTIF('2026-27 A.Y. I Sem'!F:F,A8)) -> 0 | C8: II-I CSE-E | D8: =IF(COUNTIF('2026-27 A.Y. I Sem'!F:F,C8)=0,"0",COUNTIF('2026-27 A.Y. I Sem'!F:F,C8)) -> 67 | E8: III-I CSE-E | F8: =IF(COUNTIF('2026-27 A.Y. I Sem'!F:F,E8)=0,"0",COUNTIF('2026-27 A.Y. I Sem'!F:F,E8)) -> 59 | G8: IV-I CSE-D | H8: =IF(COUNTIF('2026-27 A.Y. I Sem'!F:F,G8)=0,"0",COUNTIF('2026-27 A.Y. I Sem'!F:F,G8)) -> 56 | J8: =ROW()-ROW($K$3) -> 5 | P8: 5 | Q8: II-II CSE-A | R8: 24VE1A0527 | S8: KANDADI BHANU PRASAD | T8: II-II Attendance Detain
A9: I-I CSE-F | B9: =IF(COUNTIF('2026-27 A.Y. I Sem'!F:F,A9)=0,"0",COUNTIF('2026-27 A.Y. I Sem'!F:F,A9)) -> 0 | C9: II-I CSE-F | D9: =IF(COUNTIF('2026-27 A.Y. I Sem'!F:F,C9)=0,"0",COUNTIF('2026-27 A.Y. I Sem'!F:F,C9)) -> 68 | E9: III-I CSE-F | F9: =IF(COUNTIF('2026-27 A.Y. I Sem'!F:F,E9)=0,"0",COUNTIF('2026-27 A.Y. I Sem'!F:F,E9)) -> 59 | G9: IV-I AIML-A | H9: =IF(COUNTIF('2026-27 A.Y. I Sem'!F:F,G9)=0,"0",COUNTIF('2026-27 A.Y. I Sem'!F:F,G9)) -> 69 | J9: =ROW()-ROW($K$3) -> 6 | P9: 6 | Q9: II-II CSE-A | R9: 24VE1A0555 | S9: TEJAVATH SRINADH | T9: II-II Attendance Detain
A10: I-I CSE-G | B10: =IF(COUNTIF('2026-27 A.Y. I Sem'!F:F,A10)=0,"0",COUNTIF('2026-27 A.Y. I Sem'!F:F,A10)) -> 0 | C10: II-I CSE-G | D10: =IF(COUNTIF('2026-27 A.Y. I Sem'!F:F,C10)=0,"0",COUNTIF('2026-27 A.Y. I Sem'!F:F,C10)) -> 68 | E10: III-I CSE-G | F10: =IF(COUNTIF('2026-27 A.Y. I Sem'!F:F,E10)=0,"0",COUNTIF('2026-27 A.Y. I Sem'!F:F,E10)) -> 60 | G10: IV-I AIML-B | H10: =IF(COUNTIF('2026-27 A.Y. I Sem'!F:F,G10)=0,"0",COUNTIF('2026-27 A.Y. I Sem'!F:F,G10)) -> 67 | J10: =ROW()-ROW($K$3) -> 7 | P10: 7 | Q10: II-II CSE-A | R10: 24VE1A0558 | S10: THATTARI SNEHITH | T10: II-II Attendance Detain
A11: I-I CSE-H | B11: =IF(COUNTIF('2026-27 A.Y. I Sem'!F:F,A11)=0,"0",COUNTIF('2026-27 A.Y. I Sem'!F:F,A11)) -> 0 | C11: II-I CSE-H | D11: =IF(COUNTIF('2026-27 A.Y. I Sem'!F:F,C11)=0,"0",COUNTIF('2026-27 A.Y. I Sem'!F:F,C11)) -> 68 | E11: III-I CSE-H | F11: =IF(COUNTIF('2026-27 A.Y. I Sem'!F:F,E11)=0,"0",COUNTIF('2026-27 A.Y. I Sem'!F:F,E11)) -> 60 | G11: IV-I AIML-C | H11: =IF(COUNTIF('2026-27 A.Y. I Sem'!F:F,G11)=0,"0",COUNTIF('2026-27 A.Y. I Sem'!F:F,G11)) -> 60 | J11: =ROW()-ROW($K$3) -> 8 | P11: 8 | Q11: II-II CSE-A | R11: 25VE5A0506 | S11: KUNCHALA VENKAT DINESH | T11: II-II Attendance Detain
A12: I-I CSE-J | B12: =IF(COUNTIF('2026-27 A.Y. I Sem'!F:F,A12)=0,"0",COUNTIF('2026-27 A.Y. I Sem'!F:F,A12)) -> 0 | C12: II-I CSE-J | D12: =IF(COUNTIF('2026-27 A.Y. I Sem'!F:F,C12)=0,"0",COUNTIF('2026-27 A.Y. I Sem'!F:F,C12)) -> 67 | E12: III-I CSE-J | F12: =IF(COUNTIF('2026-27 A.Y. I Sem'!F:F,E12)=0,"0",COUNTIF('2026-27 A.Y. I Sem'!F:F,E12)) -> 60 | G12: IV-I DS-A | H12: =IF(COUNTIF('2026-27 A.Y. I Sem'!F:F,G12)=0,"0",COUNTIF('2026-27 A.Y. I Sem'!F:F,G12)) -> 56 | J12: =ROW()-ROW($K$3) -> 9 | P12: 9 | Q12: II-II CSE-B | R12: 23VE1A05A7 | S12: MOHAMMAD NASEERUDDIN | T12: II-II Attendance Detain
A13: I-I CSE-K | B13: =IF(COUNTIF('2026-27 A.Y. I Sem'!F:F,A13)=0,"0",COUNTIF('2026-27 A.Y. I Sem'!F:F,A13)) -> 0 | C13: II-I CSE-K | D13: =IF(COUNTIF('2026-27 A.Y. I Sem'!F:F,C13)=0,"0",COUNTIF('2026-27 A.Y. I Sem'!F:F,C13)) -> 69 | E13: III-I CSE-K | F13: =IF(COUNTIF('2026-27 A.Y. I Sem'!F:F,E13)=0,"0",COUNTIF('2026-27 A.Y. I Sem'!F:F,E13)) -> 56 | G13: IV-I DS-B | H13: =IF(COUNTIF('2026-27 A.Y. I Sem'!F:F,G13)=0,"0",COUNTIF('2026-27 A.Y. I Sem'!F:F,G13)) -> 57 | J13: =ROW()-ROW($K$3) -> 10 | P13: 10 | Q13: II-II CSE-B | R13: 24VE1A0570 | S13: BHUKYA VISHNUVARDHAN | T13: II-II Attendance Detain
A14: I-I AIML-A | B14: =IF(COUNTIF('2026-27 A.Y. I Sem'!F:F,A14)=0,"0",COUNTIF('2026-27 A.Y. I Sem'!F:F,A14)) -> 0 | C14: II-I AIML-A | D14: =IF(COUNTIF('2026-27 A.Y. I Sem'!F:F,C14)=0,"0",COUNTIF('2026-27 A.Y. I Sem'!F:F,C14)) -> 65 | E14: III-I AIML-A | F14: =IF(COUNTIF('2026-27 A.Y. I Sem'!F:F,E14)=0,"0",COUNTIF('2026-27 A.Y. I Sem'!F:F,E14)) -> 65 | G14: IV-I DS-C | H14: =IF(COUNTIF('2026-27 A.Y. I Sem'!F:F,G14)=0,"0",COUNTIF('2026-27 A.Y. I Sem'!F:F,G14)) -> 52 | J14: =ROW()-ROW($K$3) -> 11 | P14: 11 | Q14: II-II CSE-B | R14: 24VE1A0580 | S14: JATOTH SANTHOSH | T14: II-II Attendance Detain
A15: I-I AIML-B | B15: =IF(COUNTIF('2026-27 A.Y. I Sem'!F:F,A15)=0,"0",COUNTIF('2026-27 A.Y. I Sem'!F:F,A15)) -> 0 | C15: II-I AIML-B | D15: =IF(COUNTIF('2026-27 A.Y. I Sem'!F:F,C15)=0,"0",COUNTIF('2026-27 A.Y. I Sem'!F:F,C15)) -> 64 | E15: III-I AIML-B | F15: =IF(COUNTIF('2026-27 A.Y. I Sem'!F:F,E15)=0,"0",COUNTIF('2026-27 A.Y. I Sem'!F:F,E15)) -> 68 | J15: 12 | P15: 12 | Q15: II-II CSE-B | R15: 24VE1A0584 | S15: KALLURI VARUN KARTHIK | T15: II-II Attendance Detain
A16: I-I AIML-C | B16: =IF(COUNTIF('2026-27 A.Y. I Sem'!F:F,A16)=0,"0",COUNTIF('2026-27 A.Y. I Sem'!F:F,A16)) -> 0 | C16: II-I AIML-C | D16: =IF(COUNTIF('2026-27 A.Y. I Sem'!F:F,C16)=0,"0",COUNTIF('2026-27 A.Y. I Sem'!F:F,C16)) -> 65 | E16: III-I AIML-C | F16: =IF(COUNTIF('2026-27 A.Y. I Sem'!F:F,E16)=0,"0",COUNTIF('2026-27 A.Y. I Sem'!F:F,E16)) -> 68 | J16: 13 | P16: 13 | Q16: II-II CSE-B | R16: 25VE5A0511 | S16: PANGA CHARAN TEJA | T16: II-II Attendance Detain
A17: I-I AIML-D | B17: =IF(COUNTIF('2026-27 A.Y. I Sem'!F:F,A17)=0,"0",COUNTIF('2026-27 A.Y. I Sem'!F:F,A17)) -> 0 | C17: II-I AIML-D | D17: =IF(COUNTIF('2026-27 A.Y. I Sem'!F:F,C17)=0,"0",COUNTIF('2026-27 A.Y. I Sem'!F:F,C17)) -> 63 | J17: =ROW()-ROW($K$3) -> 14 | P17: 14 | Q17: II-II CSE-C | R17: 24VE1A05D3 | S17: DONGALA VENU | T17: II-II Attendance Detain
B18: =SUM(B3:B17) -> 0 | D18: =SUM(D3:D17) -> 998 | F18: =SUM(F3:F17) -> 863 | H18: =SUM(H3:H17) -> 750 | J18: =ROW()-ROW($K$3) -> 15 | P18: 15 | Q18: II-II CSE-C | R18: 24VE1A05F9 | S18: MOHAMMED IMTIYAZ | T18: II-II Attendance Detain
J19: =ROW()-ROW($K$3) -> 16 | P19: 16 | Q19: II-II CSE-D | R19: 24VE1A05N2 | S19: MARRI SHARANYA SRI | T19: II-II Attendance Detain
J20: =ROW()-ROW($K$3) -> 17 | P20: 17 | Q20: II-II CSE-D | R20: 24VE1A05N3 | S20: MOHAMMAD JAFFAR | T20: II-II Attendance Detain
A21: Branch/YrSem | B21: I-I | C21: II-I | D21: III-I | E21: IV-I | F21: Total | J21: =ROW()-ROW($K$3) -> 18 | P21: 18 | Q21: II-II CSE-E | R21: 24VE1A05T2 | S21: DEVGODE AJAY KUMAR | T21: II-II Attendance Detain
A22: ECE | B22: =SUM(B3) -> 0 | C22: =SUM(D3) -> 62 | D22: =SUM(F3) -> 69 | E22: =SUM(H3:H4) -> 128 | F22: =SUM(B22:E22) -> 259 | J22: =ROW()-ROW($K$3) -> 19 | P22: 19 | Q22: II-II CSE-E | R22: 24VE1A05U4 | S22: JATOTH SHIVA | T22: II-II Attendance Detain
A23: CSE | B23: =SUM(B4:B13) -> 0 | C23: =SUM(D4:D13) -> 679 | D23: =SUM(F4:F13) -> 593 | E23: =SUM(H5:H8) -> 261 | F23: =SUM(B23:E23) -> 1533 | J23: =ROW()-ROW($K$3) -> 20 | P23: 20 | Q23: II-II CSE-E | R23: 24VE1A05X5 | S23: YARABOLU NARASIMHA REDDY | T23: II-II Attendance Detain
A24: AIML | B24: =SUM(B4:B13) -> 0 | C24: =SUM(D14:D17) -> 257 | D24: =SUM(F14:F16) -> 201 | E24: =SUM(H9:H11) -> 196 | F24: =SUM(B24:E24) -> 654 | J24: =ROW()-ROW($K$3) -> 21 | P24: 21 | Q24: II-II CSE-F | R24: 24VE1A05Z5 | S24: KANCHARLA NISHANTH REDDY | T24: II-II Attendance Detain
A25: DS | B25: -- | C25: -- | D25: -- | E25: =SUM(H12:H14) -> 165 | F25: =SUM(B25:E25) -> 165 | J25: =ROW()-ROW($K$3) -> 22 | P25: 22 | Q25: II-II CSE-F | R25: 24VE1A05AH | S25: LAKAVATH DHANUSH NAIK | T25: II-II Attendance Detain
J26: =ROW()-ROW($K$3) -> 23 | P26: 23 | Q26: II-II CSE-F | R26: 25VE5A0534 | S26: MEKALA SOUMYA | T26: II-II Attendance Detain
A27: Total | B27: =SUM(B22:B26) -> 0 | C27: =SUM(C22:C26) -> 998 | D27: =SUM(D22:D26) -> 863 | E27: =SUM(E22:E26) -> 750 | F27: =SUM(F22:F26) -> 2611 | J27: =ROW()-ROW($K$3) -> 24 | P27: 24 | Q27: II-II CSE-G | R27: 23VE1A05P4 | S27: PUTTA VATHSALYANAND REDDY | T27: II-II Attendance Detain
H28: Updated on: 29th May 2026 by TSP | J28: =ROW()-ROW($K$3) -> 25 | P28: 25 | Q28: II-II CSE-G | R28: 24VE1A05DT | S28: PAKKIRI HUSSAIN VALI | T28: II-II Attendance Detain
J29: =ROW()-ROW($K$3) -> 26 | P29: 26 | Q29: II-II CSE-H | R29: 23VE1A05R2 | S29: UPPUTHOLLA NEELAKANTA NIKHIL | T29: II-II Attendance Detain
J30: =ROW()-ROW($K$3) -> 27 | P30: 27 | Q30: II-II CSE-J | R30: 23VE1A05K4 | S30: AKULA SAI NISHANTH | T30: II-II Attendance Detain
J31: =ROW()-ROW($K$3) -> 28 | P31: 28 | Q31: II-II CSE-J | R31: 23VE1A05M3 | S31: KARVA HARSHITH | T31: II-II Attendance Detain
J32: =ROW()-ROW($K$3) -> 29 | P32: 29 | Q32: II-II CSE-J | R32: 24VE1A05HJ | S32: DASARI HANUMA HARSHITH | T32: II-II Attendance Detain
J33: =ROW()-ROW($K$3) -> 30 | P33: 30 | Q33: II-II CSE-J | R33: 24VE1A05JG | S33: KORRA NIKITHA | T33: II-II Attendance Detain
J34: =ROW()-ROW($K$3) -> 31 | P34: 31 | Q34: II-II CSE-J | R34: 24VE1A05JM | S34: MANCHALA NAVADEEP | T34: II-II Attendance Detain
P35: 32 | Q35: II-II CSE-J | R35: 24VE1A05KF | S35: TEJAVATH DURGESH NAIK | T35: II-II Attendance Detain
P36: 33 | Q36: II-II CSE-J | R36: 24VE1A05KJ | S36: VULLUPALA SRIKAR REDDY | T36: II-II Attendance Detain
L37: Privious Sem. | M37: 3331 | P37: 34 | Q37: II-II CSE-K | R37: 23VE1A05Q6 | S37: SIRIPURAPU KRISHNA PAVANI | T37: II-II Attendance Detain
L38: Att+Cre +TC+Exp (Minus) | P38: 35 | Q38: II-II AIML-A | R38: 23VE1A66D7 | S38: BENJARI KETHAN GOUD | T38: II-II Attendance Detain
L39: I Year Admissions (Plus) | P39: 36 | Q39: II-II AIML-A | R39: 24VE1A6602 | S39: ALLAVARAPU SUHANI | T39: II-II Attendance Detain
L40: LES Admissions (Plus)
...

Sheet 2-1A
A1: S.NO | B1: H.T.NO | C1: STUDENT NAME | D1: FATHER NAME | E1: MOTHER NAME | F1: GENDER | G1: ST.NO | H1: P.NO | I1: MAIL ID
A2: 1 | B2: 24VE1A6684 | C2: GURSINGA RANADHEER KUMAR | D2: GURSINGA SRINIVAS | E2: GURSINGA MANJULA | F2: Male | G2: 8247432012 | H2: 9951621816 | I2: rgursinga@gmail.com
A3: 2 | B3: 25VE1A6601 | C3: ABBAYYA A | D3: AYYAGARI PATTABHI RAMAYYA | E3: MADHAVILATHA G A | F3: Female | G3: 9848035393 | H3: 9848707713 | I3: abbayyaayyagari@gmail.com
A4: 3 | B4: 25VE1A6602 | C4: BANDARI SATHWIKA | D4: BANDARI SRINIVAS | E4: BANDARI MADHAVI | F4: Female | G4: 6281583640 | H4: 7893444009 | I4: neethusathwika2008@gmail.com
A5: 4 | B5: 25VE1A6603 | C5: BANDARI SHIRISHA | D5: BANDARI SHANTHAPPA | E5: BANDARI SHANTHI | F5: Female | G5: 8519935868 | H5: 9392159488 | I5: shirishabandari24@gmail.com
A6: 5 | B6: 25VE1A6604 | C6: BANDOTHU SAI KUMAR | D6: BANDOTHU LACHIRAM | E6: BANDOTHU KAMSHELI | F6: Male | G6: 9177666126 | H6: 9100210291 | I6: saikumar05848@gmail.com
A7: 6 | B7: 25VE1A6605 | C7: BEEMAGONI VIDYA | D7: BEEMAGONI SHEKHAR | E7: BEEMAGONI KAVITHA | F7: Female | G7: 7780695553 | H7: 7660880776 | I7: beemagonividya@gmail.com
A8: 7 | B8: 25VE1A6606 | C8: BITTLA VISHAL REDDY | D8: BITTLA VENKAT REDDY | E8: BITTLA SWATHI | F8: Male | G8: 9281001295 | H8: 9550584685 | I8: vishalreddybitla@gmail.com
A9: 8 | B9: 25VE1A6607 | C9: DARAVATH SAI PRIYA | D9: V D FAKEERA NAIK | E9: DARAVATH KARUNA SREE | F9: Female | G9: 9182624239 | H9: 9014415219 | I9: saipriya901441@gmail.com
A10: 9 | B10: 25VE1A6608 | C10: DEEPSHIKA DHARNI | D10: DHARNI ANIL KUMAR | E10: DHARNI SARIKA | F10: Female | G10: 9392080334 | H10: 8328688536 | I10: deepshikadharni07@gmail.com
A11: 10 | B11: 25VE1A6609 | C11: DHARMA BHAVISHYA | D11: DHARMA BHASKAR REDDY | E11: DHARMA MAMATHA | F11: Female | G11: 8464872785 | H11: 9010243479 | I11: bhavishyar21@gmail.com
A12: 11 | B12: 25VE1A6610 | C12: DODDARAPU LINGASWAMY | D12: DODDARAPU PARUSHARAMULU | E12: DODDARAPU MANJULA | F12: Male | G12: 7569823652 | H12: 8639359760 | I12: doddarapulingaswamy@gmail.com
A13: 12 | B13: 25VE1A6611 | C13: ELE ABHINAV | D13: ELE RAMAKRISHNA | E13: ELE ROOPA | F13: Male | G13: 9063400307 | H13: 7287875104 | I13: abhinavele69@gmail.com
... A63: 62 | B63: 25VE1A6662 | C63: VAJJALA TEJASWINI | D63: MURALI | E63: UMA RANI | F63: Female | G63: 7658975829 | H63: 9700603601 | I63: tejaswini509@gmail.com
A64: 63 | B64: 25VE1A6663 | C64: VARIKUPPALA SHRAVAN KUMAR | D64: VARIKUPPALA VENKATESH | E64: VARIKUPPALA PADMA | F64: Male | I64: 25VE1A6663@sreyas.ac.in
A65: 64 | B65: 25VE1A6664 | C65: VEERAMALLA TARUNI | D65: VEERAMALLA VENKAT RAMANA | E65: VEERAMALLA SHILPA | F65: Female | G65: 8019381228 | H65: 9550313646 | I65: taruniveeramalla@gmail.com
A66: 65 | B66: 25VE1A6665 | C66: YEJARLA KETHINI | D66: YEJARLA NARASINGA RAO | E66: YEJARLA KOTESWARAMMA | F66: Female | G66: 9110334936 | H66: 9948535216 | I66: kethiniyejarla@gmail.com

Sheet 2-1B
A1: S.NO | B1: H.T.NO | C1: STUDENT NAME | D1: FATHER NAME | E1: MOTHER NAME | F1: GENDER | G1: ST.NO | H1: P.NO | I1: MAIL ID
A2: 1 | B2: 24VE1A6635 | C2: MOHAMMED MUNEEB SAYEED | D2: MOHAMMED ARIF SAYEED | E2: SIDDIQUA | F2: Male | G2: 8328447271 | H2: 7207470949 | I2: muneebsayeed07@gmail.com
A3: 2 | B3: 25VE1A6666 | C3: ABIVARNYA ANEGOUNI | D3: ANEGOUNI GOUTHAM RAJ | E3: ANEGOUNI JAGADEESHWARI | F3: Male | G3: 8498855556 | H3: 8099449908 | I3: anegouni.abivarnya@gmail.com
A4: 3 | B4: 25VE1A6667 | C4: AEDURUGATLA KRISHNAVENI | D4: AEDURUGATLA NARENDAR | E4: AEDURUGATLA SUSHILA | F4: Female | G4: 8121650984 | H4: 6303554886 | I4: krishnaveniaedurugatla@gmail.com
A5: 4 | B5: 25VE1A6668 | C5: AENUGULA JAYARANI | D5: AENUGULA SAMPATH | E5: AENUGULA BHAGYA LAKSHMI | F5: Female | G5: 8985693297 | H5: 9441846113 | I5: anugulajayarani@gmail.com
A6: 5 | B6: 25VE1A6669 | C6: AVULA ADITHYA | D6: AVULA KRISHNA | E6: AVULA KAVITHA | F6: Male | G6: 9963833875 | H6: 7093451158 | I6: adithyaavula@78gmail.com
A7: 6 | B7: 25VE1A6670 | C7: AVULA SHESHANTH | D7: AVULA VENKATESH | E7: AVULA DEEPIKA | F7: Male | G7: 8978720265 | H7: 9014132475 | I7: sheshantha83@gmail.com
A8: 7 | B8: 25VE1A6671 | C8: BADDAM RAMYA REDDY | D8: BADDAM VENKAT REDDY | E8: BADDAM RANI | F8: Female | G8: 9391842449 | H8: 9866823227 | I8: bkirthir@gmail.com
A9: 8 | B9: 25VE1A6672 | C9: BANDARI SEVANTHIKA | D9: BANDARI RAVI KUMAR | E9: B ARCHANA | F9: Female | G9: 7702394949 | H9: 9885664563 | I9: bandarisevanthika@gmail.com
A10: 9 | B10: 25VE1A6673 | C10: BANDARI SNEHA | D10: BANDARI KRISHNAKAR | E10: SRIRAMASHETTI RADHIKA | F10: Female | G10: 8520050656 | H10: 9618106643 | I10: snehabandari0@gmail.com
A11: 10 | B11: 25VE1A6674 | C11: BOINAPALLY SREE VARNITHA | D11: BOINAPALLY VENKAT RAM MOHAN RAO | E11: BOINAPALLY RAMA DEVI | F11: Female | G11: 7993729448 | H11: 9848227191 | I11: varnitha2008@gmail.com
A12: 11 | B12: 25VE1A6675 | C12: BOMMU STHITHA PRAGNA | D12: SHANKARAIAH | E12: PADMA | F12: Female | G12: 9490690195 | H12: 9848877566 | I12: sthithapragnabommu@gmail.com
A13: 12 | B13: 25VE1A6676 | C13: BURUGU AKHIL | D13: SAIDULU | E13: ANITHA | F13: Male | G13: 7989613346 | H13: 7660843206 | I13: akhilburugu07@gmail.com
... A15: 14 | B15: 25VE1A6678 | C15: CHELAMALA GURUMURTHI | D15: CHELAMALA EDUKONDALU | E15: CHELAMALA SRILATHA | F15: Male | G15: 6304169654 | H15: 9705892737 | I15: chelamalagurumurthi@gmail.com
A16: 15 | B16: 25VE1A6679 | C16: CHIKURI SHIVA CHARAN | D16: CHIKURI KRISHNA | E16: CHIKURI NAGAMANI | F16: Male | I16: 25VE1A6679@sreyas.ac.in
A17: 16 | B17: 25VE1A6680 | C17: CHINTA ROBINSON OPHIR | D17: CHINTA EMMANUEL ROBINSON | E17: CHINTA BEULAH BLESSEENA | F17: Female | G17: 7416720040 | H17: 8341050040 | I17: 25ve1a6680@gmail.com
A18: 17 | B18: 25VE1A6681 | C18: CHITTI RUSHIKESH REDDY | D18: CHITTI RAJENDAR REDDY | E18: CHITTI SWATHI | F18: Male | G18: 9347236149 | H18: 9704602768 | I18: chittirushikeshreddy3@gmail.com
A19: 18 | B19: 25VE1A6682 | C19: DANDU SHRUTHI | D19: D RAMESHWAR | E19: D RAJINI | F19: Female | G19: 9292302457 | H19: 7981282931 | I19: rajaniDandu16@gmail.com
A20: 19 | B20: 25VE1A6683 | C20: DEEKONDA ABHIRAM | D20: DEEKONDA SRINIVAS | E20: DEEKONDA KAVITHA | F20: Male | G20: 7674061107 | H20: 9849110084 | I20: abhiramdeekonda6@gmail.com
A21: 20 | B21: 25VE1A6684 | C21: DESHPEDDI ADITYA | D21: DESHPEDDI VINOD KUMAR | E21: SALLA SANDEEPA | F21: Male | G21: 8639961807 | H21: 9908886622 | I21: adityad2617@gmail.com
A22: 21 | B22: 25VE1A6685 | C22: DEVANSH SINGH | D22: BALAJI SINGH | E22: SWETHA SINGH | F22: Male | G22: 9391630339 | H22: 7981193400 | I22: mrdevansh91@gmail.com
A23: 22 | B23: 25VE1A6686 | C23: DHRUV CHAVAN | D23: MARTHAND RAO CHAVAN | E23: VASANTHA CHAVAN | F23: Male | G23: 9398023881 | H23: 9246358441 | I23: chavandhruv203@gmail.com
A24: 23 | B24: 25VE1A6687 | C24: DIVILA SRINIDHI | D24: DIVILA KONDAM RAJU | E24: DIVILA JYOTHI | F24: Female | G24: 9441634638 | H24: 9949404864 | I24: divilasrinidhi@gmail.com
A25: 24 | B25: 25VE1A6688 | C25: DONTHARABOYINA BHANU SRI | D25: DONTHARABOYINA YADAGIRI | E25: DONTHARABOYINA KALAVATHI | F25: Female | G25: 7386053804 | H25: 7036290124 | I25: dontharaboinasaiteja@gmail.com
A26: 25 | B26: 25VE1A6689 | C26: G AKSHAI KUMAR REDDY | D26: G RAJENDHER REDDY | E26: G MANJULA | F26: Male | G26: 9346380508 | H26: 7989083446 | I26: akshaynull24@gmail.com
A27: 26 | B27: 25VE1A6690 | C27: GANAGANI ARCHANA | D27: GANAGANI NAGESH | E27: GANAGANI SRUJANA | F27: Female | G27: 9347811588 | H27: 9951311588 | I27: archanaganagani9642@gmail.com
A28: 27 | B28: 25VE1A6691 | C28: GANGULA LOKESH | D28: GANGULA VENKANNA | E28: GANGULA SHOBHA | F28: Male | G28: 9908529754 | H28: 9160029754 | I28: lokeshgangula2@gmail.com
... A38: 37 | B38: 25VE1A66A2 | C38: KUNA ABHISHEK | D38: KUNA MALLIKARJUN | E38: KUNA SARITHA | F38: Male | G38: 7207859852 | H38: 9849149069 | I38: kunamallikarjun@gmail.com
A39: 38 | B39: 25VE1A66A3 | C39: KUNDE BHARGAVA | D39: KUNDE SUDHEER KUMAR | E39: KUNDE RADHIKA | F39: Male | I39: 25VE1A66A3@sreyas.ac.in
A40: 39 | B40: 25VE1A66A4 | C40: KURMETI NARASIMHA | D40: KURMETI POCHAIAH | E40: KURMETI PARVATHAMMA | F40: Male | G40: 6281959104 | H40: 9000116368 | I40: kurmetinarsi@gmail.com
A41: 40 | B41: 25VE1A66A5 | C41: MANAV BHARATHI | D41: MONI BHARATHI | E41: MANJU BHARATHI | F41: Male | G41: 8897920565 | H41: 8309160825 | I41: manavbharthi24@gmail.com
A42: 41 | B42: 25VE1A66A6 | C42: MANGALAMPALLI SANKEERTHANA | D42: MANAGALAMPALLI YADAGIRI | E42: MANGALAMPALLI VANI | F42: Female | G42: 7207010406 | H42: 9182668319 | I42: mskeerthana45@gmail.com
A43: 42 | B43: 25VE1A66A7 | C43: MOHAMMED FARHAN AHMED | D43: MOHAMMED IMRAN AHMED | E43: NAZIMA NASREEN | F43: Male | G43: 9703581044 | H43: 9885137000 | I43: ahmedfarhan07.md@gmail.com
A44: 43 | B44: 25VE1A66A8 | C44: NALIMELA REVANTH REDDY | D44: NALIMELA NAVEEN | E44: NALIMELA SANDHYA | F44: Male | G44: 8919246104 | H44: 9866966823 | I44: revanthlucky9866@gmail.com
A45: 44 | B45: 25VE1A66A9 | C45: NANDAIAHGARI NEHA | D45: NANDAIAHGARI RAMESH | E45: NANDAIAHGARI SHARADHA | F45: Female | G45: 9390823972 | H45: 9989128676 | I45: nandaiahgarineha@gmail.com
A46: 45 | B46: 25VE1A66B0 | C46: PANTANGI VENKATA LALITH KEYUR | D46: PANTANGI SITARAMAIAH | E46: PANTANGI VASAVI | F46: Male | G46: 8919391531 | H46: 9985381222 | I46: keyurhappy24@gmail.com
A47: 46 | B47: 25VE1A66B1 | C47: PATLOLA AKSHITHA PAATIL | D47: PATLOLA CHEN BASAPPA | E47: PATLOLA SWAPNA | F47: Female | G47: 6302233025 | H47: 8688938071 | I47: akshithapatil75@gmail.com
A48: 47 | B48: 25VE1A66B2 | C48: PINGALI SRI KUMARA VAISHNAVI | D48: PINGALI VENKATA GOPALA PAVAN KUMAR BHANU | E48: PINGALI LAKSHMI APARNA KOTESWARI | F48: Female | G48: 9959458247 | H48: 9618833999 | I48: pvaishnavi691@gmail.com
A49: 48 | B49: 25VE1A66B3 | C49: PITTALA ABHINAV | D49: PITTALA MALLESHAM | E49: PITTALA NIRMALA | F49: Male | G49: 9494723406 | H49: 9908641040 | I49: abhinavmudhiraj09@gmail.com
A50: 49 | B50: 25VE1A66B4 | C50: PITTALA VYSHNAVI | D50: PITTALA SHANKARAIAH | E50: PITTALA LALITHA | F50: Female | G50: 8179099473 | H50: 9963239754 | I50: vyshnavipittala332@gmail.com
...

Sheet 2-1C
A1: S.NO | B1: H.T.NO | C1: STUDENT NAME | D1: FATHER NAME | E1: MOTHER NAME | F1: GENDER | G1: ST.NO | H1: P.NO | I1: MAIL ID
A2: 1 | B2: 24VE1A6690 | C2: KETHAVATH VISHAL | D2: K LAXMAN NAIK | E2: K DEVI BAI | F2: Male | G2: 9391494558 | H2: 9921200298 | I2: kethavathvishal884@gmail.com
A3: 2 | B3: 25VE1A66D0 | C3: AHMEDHI SANIYA BEGUM | D3: MOHAMMED KHALEEL | E3: NASEEM BEGUM | F3: Female | G3: 8008935003 | H3: 9346924688 | I3: khaleel800893@gmail.com
A4: 3 | B4: 25VE1A66D1 | C4: ALAMPALLY ASHRITHA | D4: ALAMPALLY SANGAMESHWARLU | E4: ALAMPALLY PARAMESHWARI | F4: Female | G4: 9398479105 | H4: 6301503625 | I4: alampalliashritha@gmail.com
A5: 4 | B5: 25VE1A66D2 | C5: BAGHAVATHULA KARTHIKEYA | D5: BAGHAVATHULA RAJKUMAR | E5: BAGHAVATHULA SRILALITHA | F5: Male | I5: 25VE1A66D2@sreyas.ac.in
A6: 5 | B6: 25VE1A66D3 | C6: BANDA SHASHIDHAR REDDY | D6: BANDA PRASAD REDDY | E6: BANDA SARITHA | F6: Male | G6: 7671817011 | H6: 7671817011 | I6: shashidharreddy1404@gmail.com
A7: 6 | B7: 25VE1A66D4 | C7: BANDARI MANI PRITAM | D7: BANDARI SREEKANTH | E7: BANDARI RENUKA | F7: Male | I7: 25VE1A66D4@sreyas.ac.in
A8: 7 | B8: 25VE1A66D5 | C8: BANDARU CHAKRADHAR RAO | D8: BANDARU DAYAKAR RAO | E8: SADAMANI SUBHADRA | F8: Male | G8: 9959655733 | H8: 9959655733 | I8: 25ve1a66d5@sreyas.ac.in
A9: 8 | B9: 25VE1A66D6 | C9: BANOTHU SIDDU | D9: BANOTHU RAVI | E9: BANOTHU SAKRI | F9: Male | G9: 6304321358 | H9: 9014516742 | I9: sidhurajofficial@gmail.com
A10: 9 | B10: 25VE1A66D7 | C10: BEERAM MANASA | D10: BEERAM KONDAL REDDY | E10: BEERAM KALPANA | F10: Female | G10: 9505640159 | H10: 8106236439 | I10: beerammanasa72@gmail.com
A11: 10 | B11: 25VE1A66D8 | C11: BHOOPALA MANVITHA | D11: BHOOPALA RAVINDER | E11: BHOOPALA PADMAJA | F11: Female | G11: 8125052707 | H11: 8309818317 | I11: bhoopalamanvitha27@gmail.com
A12: 11 | B12: 25VE1A66D9 | C12: BODUPALLY VAMSHI | D12: BODUPALLY SANTOSH KUMAR | E12: BODUPALLY CHANDANA | F12: Male | G12: 7680066513 | H12: 9966406513 | I12: vamshi25ve1a66d9@gmail.com
A13: 12 | B13: 25VE1A66E0 | C13: BONAM VASANTH CHAKRI | D13: BONAM S S R GOPALA SWAMY | E13: BONAM SITA RAMA LAKSHMI | F13: Male | G13: 9533885852 | H13: 8688911241 | I13: vasanthchakri6@gmail.com
A14: 13 | B14: 25VE1A66E1 | C14: BUDURU ABHIGNA | D14: BUDURU JAGADEESHWAR REDDY | E14: BUDURU JYOTHI | F14: Female | G14: 9133902194 | H14: 9963902193 | I14: abhignareddybuduru@gmail.com
A15: 14 | B15: 25VE1A66E2 | C15: BURRI SATHVIKA | D15: BURRI RAMANA REDDY | E15: BURRI SANDHYA | F15: Female | G15: 9959506104 | H15: 9866506104 | I15: sathvikaburry@gmail.com
A16: 15 | B16: 25VE1A66E3 | C16: DAKSH NAKRANI | D16: NAKRANI PRAVEEN KUMAR | E16: NAKRANI HEENA | F16: Male | G16: 9493505167 | H16: 9949062167 | I16: dakshnakrani30@gmail.com
A17: 16 | B17: 25VE1A66E4 | C17: DASOJU GAYATHRI | D17: DASOJU ANJANEYULU | E17: DASOJU UMA | F17: Female | G17: 6300184016 | H17: 9705714844 | I17: gayathridasoju05@gmail.com
A18: 17 | B18: 25VE1A66E5 | C18: DIDDI AKSHAYYA | D18: DIDDI LAXMINARAYANA | E18: DIDDI SANDHYA KAVITHA | F18: Female | G18: 7075555596 | H18: 9866166692 | I18: akshayyadiddi@gmail.com
A19: 18 | B19: 25VE1A66E6 | C19: GAJULA SRINIDHI | D19: GAJULA GANESH | E19: GAJULA VARALAXMI | F19: Female | G19: 9666657009 | H19: 9951211751 | I19: Gajulasrinidhi23@gmail.com
... A22: 21 | B22: 25VE1A66E9 | C22: JAKKA RASAGNA | D22: JAKKA CHINNA RAJESHWAR | E22: JAKKA RAJU | F22: Female | G22: 9490918462 | H22: 9440018462 | I22: rasagnajakka@gmail.com
A23: 22 | B23: 25VE1A66F0 | C23: JAKKIDI BALA MANIKANTA REDDY | D23: JAKKIDI NARENDER REDDY | E23: JAKKIDI LAVANYA | F23: Male | I23: 25VE1A66F0@sreyas.ac.in
A24: 23 | B24: 25VE1A66F1 | C24: JILLELA UDAY SHANKAR VARAPRASAD REDDY | D24: J KARUNAKAR REDDY | E24: J VARALAKSHMI | F24: Male | G24: 8374592006 | H24: 9704117153 | I24: udayjillela24@gmail.com
A25: 24 | B25: 25VE1A66F2 | C25: KADALI KALYAN | D25: KADALI VENKATARAMANA | E25: KADALI NAGALAKSHMI | F25: Male | G25: 9948491133 | H25: 9951688140 | I25: kadalikalyan45674@gmail.com
A26: 25 | B26: 25VE1A66F3 | C26: KAKANI NAGA SAI HARITHA | D26: KAKANI RAVI KUMAR | E26: KAKANI SARADA | F26: Female | G26: 6309781273 | H26: 8464999374 | I26: nsharitha0709@gmail.com
A27: 26 | B27: 25VE1A66F4 | C27: KAMMARI LAHARI | D27: KAMMARI MOHAN CHARY | E27: KAMMARI VANI | F27: Female | G27: 9392618552 | H27: 9247856729 | I27: 25ve1a66f4@gmail.com
A28: 27 | B28: 25VE1A66F5 | C28: KANATHARAPU ASHRITHA | D28: KANATHARAPU KISHORE KUMAR | E28: KANATHARAPU KRISHNAVENI | F28: Female | G28: 7989910152 | H28: 9951355771 | I28: kishore.kanatharapu@gmail.com
A29: 28 | B29: 25VE1A66F6 | C29: KARRE BHEEMESH | D29: KARRE BHEEMSHAPPA | E29: KARRE PADMAMMA | F29: Male | G29: 8688394973 | H29: 6303401854 | I29: bheemmadival4973@gmail.com
A30: 29 | B30: 25VE1A66F7 | C30: KETHAVATH ABHILASH | D30: KETHAVATH HANUMANTHU | E30: KETHAVATH SUSHEELA | F30: Male | I30: 25VE1A66F7@sreyas.ac.in
A31: 30 | B31: 25VE1A66F8 | C31: KETHAVATH GANESH | D31: K RAGYA NAYAK | E31: K SHANTHAMMA | F31: Male | G31: 9281416643 | H31: 9010738351 | I31: kethavathg694@gmail.com
A32: 31 | B32: 25VE1A66F9 | C32: KHUDSIA SULTANA | D32: SHAIK RAHMATH ALI | E32: NAZIA SULTANA | F32: Female | G32: 7330702811 | H32: 9059902811 | I32: khudsiasultana246@gmail.com
A33: 32 | B33: 25VE1A66G0 | C33: KILAJI SAI TEJA | D33: KILAJI PRAKASH | E33: KILAJI SUJATHA | F33: Male | G33: 7207624285 | H33: 8008096895 | I33: kilajisaiteja22@gmail.com
A34: 33 | B34: 25VE1A66G1 | C34: KOYALKAR NIKITHA | D34: KOYALKAR MURALI | E34: KOYALKAR LATHA | F34: Female | G34: 8688679128 | H34: 9701528198 | I34: koyalkarnikitha2@gmail.com
A35: 34 | B35: 25VE1A66G2 | C35: KUNDAN ANKITH KUMAR | D35: K NAVEEN KUMAR | E35: K APARNA | F35: Male | G35: 8125193033 | H35: 8897950187 | I35: ankithkumarkundan@gmail.com
A36: 35 | B36: 25VE1A66G3 | C36: KURELLA VEDANTH | D36: KURELLA UDAY PRAKASH | E36: KURELLA LAXMI PRASANNA | F36: Male | G36: 8886979393 | H36: 9393979393 | I36: vedanthkurella@gmail.com
A37: 36 | B37: 25VE1A66G4 | C37: MAHESHWARAM DHANUSH VARDHAN CHARY | D37: MAHESHWARAM SRINIVAS CHARY | E37: MAHESHWARAM LAXMI | F37: Male | G37: 9573104902 | H37: 9440280924 | I37: maheshwaramdanushvardhanchary@gmail.com
A38: 37 | B38: 25VE1A66G5 | C38: MANDULA TEJASH | D38: MANDULA RAMESH KUMAR | E38: MANDULA MANJULA | F38: Male | G38: 9346509067 | H38: 9491748876 | I38: mtejash14@gmail.com
A39: 38 | B39: 25VE1A66G6 | C39: MANTHANI VIDHATHA | D39: MANTHANI VENU GOPAL | E39: M KALYANI | F39: Male | G39: 8247797008 | H39: 9346328632 | I39: vidhathamanthani@gmail.com
A40: 39 | B40: 25VE1A66G7 | C40: MOHAMMED ABDUL MUHAIMIN | D40: MOHAMMED ABDUL MUBEEN | E40: TANVEER SALMA | F40: Male | G40: 8125372310 | H40: 9703450490 | I40: sreyas66g7@gmail.com
A41: 40 | B41: 25VE1A66G8 | C41: MUDIGONDA SINDHU | D41: MUDIGONDA MOHAN | E41: MUDIGONDA LAXMI | F41: Female | G41: 9346766314 | H41: 9866615244 | I41: sindhu280707@gmail.com
A42: 41 | B42: 25VE1A66G9 | C42: NALLA VINUTHNA | D42: NALLA SRINIVAS | E42: NALLA SABITHA | F42: Female | I42: 25VE1A66G9@sreyas.ac.in
...

Sheet 2-1D
A1: S.NO | B1: H.T.NO | C1: STUDENT NAME | D1: FATHER NAME | E1: MOTHER NAME | F1: GENDER | G1: ST.NO | H1: P.NO | I1: MAIL ID
A2: 1 | B2: 25VE1A66K4 | C2: AJMEERA ARAVIND NAYAK | D2: AJMEERA RAVI | E2: AJMEERA SUNITHA | F2: Male | G2: 9381031324 | H2: 9949319908 | I2: aravindajmeera74@gmail.com
A3: 2 | B3: 25VE1A66K5 | C3: ALLENI AAPTHI RAO | D3: ALLENI RAJASHEKAR RAO | E3: ALLENI RAMYA | F3: Female | G3: 8106979995 | H3: 9010180411 | I3: m83082181@gmail.com
A4: 3 | B4: 25VE1A66K6 | C4: ANANTHULA VEDA KEERTHI | D4: ANANTHULA VENUGOPAL | E4: ANANTHULA RAJITHA | F4: Female | G4: 9346877337 | H4: 9014951776 | I4: keerthishetty1414@gmail.com
A5: 4 | B5: 25VE1A66K7 | C5: BANDA NIKHITHA | D5: BANDA SOMALINGAM | E5: BANDA VIJAYALAKSHMI | F5: Female | G5: 9347811755 | H5: 9396623384 | I5: nikhithabanda4@gmail.com
A6: 5 | B6: 25VE1A66K8 | C6: BANDI BHANUPRAKASH | D6: BANDI RAVI | E6: BANDI JYOTHI | F6: Male | G6: 6303008993 | H6: 9949293712 | I6: bhanuprakashbandi656@gmail.com
A7: 6 | B7: 25VE1A66K9 | C7: BATHULA SAHASRA | D7: BATHULA SRINIVAS | E7: BATHULA SARITHA | F7: Female | G7: 8500818889 | H7: 9866670707 | I7: sahasrabathula8889@gmail.com
A8: 7 | B8: 25VE1A66L0 | C8: BHUDIDHA BHADRINATH | D8: BHUDIDHA ANJAIAH | E8: BHUDIDHA LAKSHMI | F8: Male | G8: 6304827624 | H8: 6304827624 | I8: 25ve1a66l0@gmail.com
A9: 8 | B9: 25VE1A66L1 | C9: BODDUPELLI PRANEESH KUMAR | D9: BODDUPELLI VENKANNA | E9: BODDUPELLI SRILATHA | F9: Male | G9: 9398805997 | H9: 6303923306 | I9: praneshboddupalli369@gmail.com
A10: 9 | B10: 25VE1A66L2 | C10: BOMMU MOUNIKA | D10: BOMMU ANJANEYULU | E10: BOMMU DHANAMMA | F10: Female | G10: 9398676188 | H10: 6303789546 | I10: 25ve1a66l2@gmail.com
A11: 10 | B11: 25VE1A66L3 | C11: CHEERLA ANVITH | D11: CHEERLA MAHESH | E11: CHEERLA SANDHYA | F11: Male | G11: 6303319523 | H11: 7386862829 | I11: anvithch125@gmail.com
A12: 11 | B12: 25VE1A66L4 | C12: CHINNAM NIDHI SRI | D12: CHINNAM MALLESH | E12: CHINNAM SRILATHA | F12: Female | I12: 25VE1A66L4@sreyas.ac.in
A13: 12 | B13: 25VE1A66L5 | C13: DASARI SANJANA | D13: DASARI RAMAIAH | E13: DASARI SWATHI | F13: Female | G13: 7997499382 | H13: 7661073750 | I13: dasarisanjana07@gmail.com
A14: 13 | B14: 25VE1A66L6 | C14: DHARAVATH NITHIN | D14: DHARAVATH SUNDAR | E14: DHARAVATH JYOTHI | F14: Male | G14: 9346300824 | H14: 9640017649 | I14: 25ve1a66l6@gmail.com
A15: 14 | B15: 25VE1A66L7 | C15: EDULA AMULYA | D15: EDULA SRI RAMULU | E15: EDULA RENUKA | F15: Female | G15: 9390217935 | H15: 9390217935 | I15: edulaamulya2@gmail.com
A16: 15 | B16: 25VE1A66L8 | C16: EITTY SAI CHARAN REDDY | D16: EITTY ANAND REDDY | E16: EITTY SUNITHA | F16: Male | G16: 8688007119 | H16: 7013775209 | I16: eittysaicharanreddy2020@gmail.com
A17: 16 | B17: 25VE1A66L9 | C17: EMMADISHETTI VISHWAK SEN | D17: EMMADISHETTI NARSIMHA | E17: EMMADISHETTI SUNITHA | F17: Male | G17: 9492644229 | H17: 8121903030 | I17: vishwaksen111@gmail.com
A18: 17 | B18: 25VE1A66M0 | C18: G CHINMA YI SAI | D18: G NAVEEN CHARY | E18: G LAVANYA | F18: Female | G18: 9347146535 | H18: 9346296286 | I18: chinmayisaigundoju@gmail.com
A19: 18 | B19: 25VE1A66M1 | C19: GANJI BALA SHREYAS REDDY | D19: GANJI BHASKER REDDY | E19: GANJI ARUNA | F19: Male | G19: 9030718287 | H19: 8247316331 | I19: fredshreyas@gmail.com
A20: 19 | B20: 25VE1A66M2 | C20: GANJI SUJITHA | D20: GANJI ANJAIAH | E20: GANJI ANITHA | F20: Female | G20: 6309739429 | H20: 8106402550 | I20: ganji.sujitha2007@gmail.com
A21: 20 | B21: 25VE1A66M3 | C21: GOLI YASHWASIN | D21: G R SRAVAN KUMAR | E21: G SANTOSHINI | F21: Male | G21: 9515765250 | H21: 9849526115 | I21: yashwasin24@gmail.com
A22: 21 | B22: 25VE1A66M5 | C22: HASINI REDDY | D22: KARUNKAR REDDY | E22: SADHANA REDDY | F22: Female | G22: 7093604795 | H22: 9989785695 | I22: ghasinireddy2007@gmail.com
A23: 22 | B23: 25VE1A66M6 | C23: JAGAPATHI KEERTHANA | D23: JAGAPATHI VIKRAM | E23: JAGAPATHI VEENA | F23: Female | G23: 9390299616 | H23: 9030424813 | I23: jkeerthana24107@gmail.com
A24: 23 | B24: 25VE1A66M7 | C24: KADAARI MOKSHIT | D24: KADAARI VIKRAM BABU | E24: CHALUVALA SARITHA | F24: Male | G24: 9502031383 | H24: 9866243463 | I24: k.mokshit2007@gmail.com
... A64: 63 | B64: 25VE1A66R7 | C64: Y ANUSH BHAVYA | D64: Y SRIKANTH | E64: Y SUNEETHA | F64: Female | G64: 7661830694 | H64: 9603803286 | I64: bhavya.anush2041@gmail.com

Sheet 3-1A
A1: S.NO | B1: H.T.NO | C1: STUDENT NAME | D1: FATHER NAME | E1: MOTHER NAME | F1: GENDER | G1: ST.NO | H1: P.NO | I1: MAIL ID
A2: 1 | B2: 23VE1A66G5 | C2: MEKALA ANUROOP | D2: MEKALA GOPAL | E2: MEKALA SUBHADRA | F2: Male | G2: 8309424421 | H2: 9392996460 | I2: anuroopmekala0@gmail.com
A3: 2 | B3: 24VE1A6601 | C3: ALIMPARAMBATH YESHASHRI | D3: ALIMPARAMBATH HARI KUMAR | E3: ALIMPARAMBATH LAKSHMI PRASANNA | F3: Female | G3: 7989344280 | H3: 7989325219 | I3: yeshasri8@gmail.com
A4: 3 | B4: 24VE1A6603 | C4: ALLIBADA ABHINAV GOUD | D4: ALLIBADA POORNA CHANDRA GOUD | E4: ALLIBADA SARITHA KALYANI | F4: Male | G4: 9290096795 | H4: 9247549777 | I4: goudabhinav828@gmail.com
A5: 4 | B5: 24VE1A6604 | C5: ARYAN RAVI MESHRAM | D5: RAVI SHRIRANG MESHRAM | E5: SUDHA RAVI MESHRAM | F5: Male | G5: 7382969383 | H5: 9848034113 | I5: aryanravim1712@gmail.com
A6: 5 | B6: 24VE1A6605 | C6: BELLAMKONDA KUSHAL REDDY | D6: BELLAMKONDA NAGI REDDY | E6: BELLAMKONDA KAVITHA | F6: Male | G6: 8919284099 | H6: 9398016551 | I6: bellamkondakushalreddy14@gmail.com
A7: 6 | B7: 24VE1A6606 | C7: BIRADAR AKSHITHA | D7: BIRADAR ASHOK | E7: BIRADAR RENUKA | F7: Female | G7: 8121590621 | H7: 8125510621 | I7: akshitha.biradar599@gmail.com
A8: 7 | B8: 24VE1A6608 | C8: CHADUVULA SRAVAN KUMAR | D8: CHADUVULA VINOD | E8: CHADUVULA SRIVANI | F8: Male | G8: 9059789311 | H8: 9177989311 | I8: sravanchaduvula@gmail.com
A9: 8 | B9: 24VE1A6609 | C9: CHANDRAGIRI TANUSH | D9: C VIJAY | E9: C TANUJA | F9: Male | G9: 6300188653 | H9: 9848060369 | I9: ctannush@gmail.com
A10: 9 | B10: 24VE1A6610 | C10: CHINTHAREDDY MOHITH REDDY | D10: CHINTHA REDDY SATYANARAYANA REDDY | E10: CHINTHAREDDY LAKSHMI | F10: Male | G10: 9392441837 | H10: 9704122384 | I10: 24VE1A6610@gmail.com
A11: 10 | B11: 24VE1A6611 | C11: CHITYALA SATYAGNANI | D11: C VENU GOPAL | E11: C MANJULA | F11: Male | G11: 6305863660 | H11: 6305863660 | I11: satyagnani4136@gmail.com
A12: 11 | B12: 24VE1A6612 | C12: DASARI SIRI CHANDANA | D12: D SATHYANARAYANA | E12: D MONIKA | F12: Female | G12: 9640531099 | H12: 9396640704 | I12: monikadomr@gmail.com
A13: 12 | B13: 24VE1A6613 | C13: DHARAVATH KISHORE NAYAK | D13: DHARAVATH HONA | E13: DHARVATH | F13: Male | G13: 9059620284 | H13: 9948346368 | I13: dharavathkishorenayak626@gmail.com
... A66: 65 | B66: 25VE5A6606 | C66: VALUVURI PRAVEEN | D66: VALUVURI SHOBUN BABU | E66: VALUVURI SUMALATHA | F66: Male | G66: 8978518587 | H66: 8099394005 | I66: valuvuripraveen@gmail.com

Sheet 3-1B
A1: S.NO | B1: H.T.NO | C1: STUDENT NAME | D1: FATHER NAME | E1: MOTHER NAME | F1: GENDER | G1: ST.NO | H1: P.NO | I1: MAIL ID
A2: 1 | B2: 22VE1A6625 | C2: KETHAVATH CHAITANYA | D2: KETHAVATH DHAKYA | F2: Male | G2: 9346328325 | H2: 9542939923 | I2: chaitanyakethavath@gmail.com
A3: 2 | B3: 22VE1A6662 | C3: UPPULA MAHESH | D3: UPPULA LINGAIAH | F3: Male | G3: 6302054605 | H3: 6302054605 | I3: maheshuppula245@gmail.com
A4: 3 | B4: 24VE1A6665 | C4: ADULA MYTHILI | D4: ADULA KIRAN KUMAR | E4: ADULA RAJITHA | F4: Female | G4: 8106036829 | H4: 9550911235 | I4: mythilikiran15@gmail.com
A5: 4 | B5: 24VE1A6666 | C5: ALLA PARDHASARADHI | D5: ALLA RAMBABU | E5: ALLA RADHA | F5: Male | G5: 6303932503 | H5: 7993049415 | I5: pardhuchowdaryalla19@gmail.com
A6: 5 | B6: 24VE1A6667 | C6: AMGOTHU AKHILA | D6: AMGOTHU VENU | E6: AMGOTHU VIJAYA | F6: Female | G6: 9346769058 | H6: 9949679903 | I6: akhilaamgoth16@gmail.com
A7: 6 | B7: 24VE1A6668 | C7: ANKAM HANSSIKA | D7: ANKAM GOPI | E7: ANKAM SUNITHA | F7: Female | G7: 7660978003 | H7: 9000008412 | I7: hanssikaankam@gmail.com
A8: 7 | B8: 24VE1A6669 | C8: B NEERAJ | D8: B MADHU MOHAN | E8: B CHARITHA | F8: Male | G8: 8247350779 | H8: 9866440183 | I8: bandiganeeraj@gmail.com
A9: 8 | B9: 24VE1A6670 | C9: BACHIREDDY ASHRITH REDDY | D9: BACHIREDDY RAJENDER REDDY | E9: BACHIREDDY GIRIJA REDDY | F9: Male | G9: 9346815436 | H9: 6302591994 | I9: ashrithr447@gmail.com
A10: 9 | B10: 24VE1A6671 | C10: BANDARI KAIVALYA NANDANA | D10: BANDARI RAMAKRISHNA | E10: B HARINI | F10: Female | G10: 8341192829 | H10: 9553363065 | I10: kaivalyabandari@gmail.com
A11: 10 | B11: 24VE1A6672 | C11: BARLA ASRITHA REDDY | D11: BARLA SANTHOSH REDDY | E11: BARLA KAVITHA | F11: Female | G11: 9912121696 | H11: 9010367029 | I11: asrithareddy58@gmail.com
A12: 11 | B12: 24VE1A6673 | C12: CHALAMALASETTY JAHNAVI GIRIJA | D12: CHALAMALASETTI RAMESH | E12: CH. KRISHNA PRIYA | F12: Female | G12: 9032834234 | H12: 9885675557 | I12: jahnavinaidu2006@gmail.com
A13: 12 | B13: 24VE1A6675 | C13: CHEGURI SAI CHARAN | D13: CHEGURI SUDHAKAR | E13: CHEGURI BALAMANI | F13: Male | G13: 7032338178 | H13: 9951078009 | I13: 24VE1A6675@gmail.com
A14: 13 | B14: 24VE1A6676 | C14: CHILLA ASMITHA | D14: CHILLA SRINIVAS REDDY | E14: CHILLA KAVITHA | F14: Female | G14: 8185913171 | H14: 9959863090 | I14: asmithareddy9959@gmail.com
A15: 14 | B15: 24VE1A6677 | C15: DOMA AJAY | D15: DOMA SRINIVASULU | E15: DOMA SARASWATHI | F15: Male | G15: 8008958089 | H15: 9704651379 | I15: domaajay187@gmail.com
... A50: 49 | B50: 24VE1A66B4 | C50: RAMAVATH SAILAJA | D50: RAMAVATH RAMJAN | E50: RAMAVATH UMA | F50: Female | G50: 8247433088 | H50: 7013811393 | I50: shailajaramavath44@gmail.com
A51: 50 | B51: 24VE1A66B6 | C51: RAYEENI SANTHOSH | D51: RAYEENI AMARENDRANATH | E51: 0 | F51: Male | G51: 9550109578 | H51: 9492199685 | I51: 24VE1A66B6@gmail.com
A52: 51 | B52: 24VE1A66B7 | C52: RUDRA NARAYAN ROUT | D52: `ARUN ROUT | E52: KALPANA ROUT | F52: Male | G52: 8179342532 | H52: 8179691352 | I52: rajarout1022@gmail.com
A53: 52 | B53: 24VE1A66B8 | C53: SAMA JITHIN REDDY | D53: SAMA SURESH REDDY | E53: SAMA HEMALATHA REDDY | F53: Male | G53: 9676174111 | H53: 8332952085 | I53: chatti.reddy@gmail.com
A54: 53 | B54: 24VE1A66B9 | C54: SARA SRINIDHI | D54: SARA SHIVA KUMAR | E54: SARA MADHAVI | F54: Female | G54: 6301962125 | H54: 9346692654 | I54: sarasrinidhi78@gmail.com
A55: 54 | B55: 24VE1A66C0 | C55: SARAGUNDLA PRANATHI | D55: SARAGUNDLA YALLAIAH | E55: SARAGUNDLA MAHIBOOBA | F55: Female | G55: 9182609603 | H55: 9010290761 | I55: saragundlapranathi@gmail.com
A56: 55 | B56: 24VE1A66C1 | C56: SHAIK MALIK | D56: SHAIK MADHAR SHAH VALI | E56: SHAIK HALEEMA | F56: Male | G56: 9866215592 | H56: 9866615592 | I56: shaikmalik1608@gmail.com
A57: 56 | B57: 24VE1A66C2 | C57: SIRIPOTHU ANU | D57: SIRIPOTHU VENKAT KUMAR | E57: SIRIPOTHU KARUNA | F57: Female | G57: 9866818911 | H57: 9866655543 | I57: anusri26633@gmail.com
A58: 57 | B58: 24VE1A66C3 | C58: SUSHITH NUNEMUNTHALA | D58: SUDHEER NUNEMUNTHALA | E58: LILY LOTHUKUNTA | F58: Male | G58: 7780390482 | H58: 9870814464 | I58: sushith.nunemunthala@gmail.com
A59: 58 | B59: 24VE1A66C4 | C59: THEEPI RUTHVIKA REDDY | D59: THEEPI BHASKAR REDDY | E59: THEEPI MANJULA REDDY | F59: Female | G59: 7416421655 | H59: 7981487785 | I59: rtheepi49@gmail.com
A60: 59 | B60: 24VE1A66C5 | C60: VAVILALA SAI SHRUTHI | D60: VAVILALA SRINIVAS REDDY | E60: VAVILALA PREMALATHA | F60: Female | G60: 7337262029 | H60: 9160202029 | I60: vshruthireddy11@gmail.com
A61: 60 | B61: 24VE1A66C6 | C61: VELUGU VINAY TEJA | D61: VELUGU JANAIAH | E61: VELUGU SHOBHA | F61: Male | G61: 8790404640 | H61: 9000629783 | I61: veluguvinay111@gmail.com
A62: 61 | B62: 24VE1A66C7 | C62: YASA SIRI TEJA | D62: YASA CHANDRA SHEKAR REDDY | E62: YASA KAVITHA | F62: Female | G62: 7032503240 | H62: 9346836868 | I62: yasasiri24@gmail.com
A63: 62 | B63: 24VE1A66C8 | C63: YEDULABAD AKSHAY RAJ | D63: YEDULABAD RAJASHEKAR | E63: YEDULABAD MEENA KUMARI | F63: Male | G63: 7989651337 | H63: 9247113504 | I63: y.akshayraj30@gmail.com
... A69: 68 | B69: 25VE5A6612 | C69: TUDI SRAVANI | D69: TUDI MALLESH | E69: TUDI SATHYAMMA | F69: Female | G69: 9346057038 | H69: 8179141456 | I69: sravanitudi@gmail.com

Sheet 3-1C
A1: S.NO | B1: H.T.NO | C1: STUDENT NAME | D1: FATHER NAME | E1: MOTHER NAME | F1: GENDER | G1: ST.NO | H1: P.NO | I1: MAIL ID
A2: 1 | B2: 24VE1A66C9 | C2: A GAYATHRI | D2: A GOPAL | E2: A.SHANKARAMMA | F2: Female | G2: 9177996929 | H2: 9908310989 | I2: gayathrireema1432@gmail.com
A3: 2 | B3: 24VE1A66D0 | C3: A HARINI REDDY | D3: A NAGI REDDY | E3: A MALLESWARI | F3: Female | G3: 9618864899 | H3: 7997993144 | I3: 24VE1A66D0@gmail.com
A4: 3 | B4: 24VE1A66D1 | C4: AKKINAPALLI AISHWARYA | D4: AKKINAPALLI NARENDRABABU | E4: AKKINAPALLI VANITHA | F4: Female | G4: 8247079582 | H4: 9396382982 | I4: akkinapalliaishu@gmail.com
A5: 4 | B5: 24VE1A66D2 | C5: AKSHAT RAJ | D5: MUKESH KUMAR | E5: RANJITA | F5: Male | G5: 8076358867 | H5: 8096791653 | I5: akshataraj19@gmail.com
A6: 5 | B6: 24VE1A66D3 | C6: ALIGIRI SHIVA PRASAD | D6: ALIGIRI CHANDRAMOHAN | E6: ALIGIRI LAKSHMI | F6: Male | G6: 9490777257 | H6: 7097874769 | I6: shivaaligiri@gmail.com
A7: 6 | B7: 24VE1A66D4 | C7: AMBATI ARCHANA | D7: AMBATI NARASIMHA | E7: AMBATI LAXMI | F7: Female | G7: 7893037748 | H7: 8688638085 | I7: archanaambati225@gmail.com
A8: 7 | B8: 24VE1A66D5 | C8: ATMAKUR SIDDHARTHA | D8: ATMAKUR JAGANNATH | E8: ATMAKUR NEERAJA | F8: Male | G8: 9849659106 | H8: 8919744364 | I8: sidhartha.2205@gmail.com
A9: 8 | B9: 24VE1A66D6 | C9: BAJA SRAVYA | D9: BAJA LACHULU | E9: BAJA LAXMI | F9: Female | G9: 9182802560 | H9: 9398702217 | I9: sravyabaja@gmail.com
A10: 9 | B10: 24VE1A66D7 | C10: BHUVANAGIRI SATYA SUBHASH | D10: BHUVANAGIRI SIVA KUMAR | E10: CHEENAPALLI SARITHA | F10: Male | G10: 9059980104 | H10: 7674826119 | I10: subhashbhuvanagiri9@gmail.com
A11: 10 | B11: 24VE1A66D8 | C11: BIMIDI AKHIL REDDY | D11: B RAJASHEKAR REDDY | E11: B MALINI | F11: Male | G11: 8125709823 | H11: 8074491258 | I11: bimidiakhilreddy@gmail.com
A12: 11 | B12: 24VE1A66D9 | C12: BODDU JASHWANTH REDDY | D12: BODDU BUCHI REDDY | E12: BODDU.MAMATHA | F12: Male | G12: 6300563776 | H12: 9959750112 | I12: mamathaboddu30@gmail.com
A13: 12 | B13: 24VE1A66E0 | C13: BOLLAM RISHITH | D13: BOLLAM MANIKYAM | E13: BOLLAM DEVENDRA | F13: Male | G13: 9959795645 | H13: 9848751822 | I13: rishithrishi777@gmail.com
... A69: 68 | B69: 25VE5A6618 | C69: SHEELAM VARUN | D69: SHEELAM SURESH | E69: SHEELAM MAHESHWARI | F69: Male | G69: 9347444506 | H69: 8121211242 | I69: sheelamvarun86@gmail.com

Sheet 4-1A
A1: S.NO | B1: H.T.NO | C1: STUDENT NAME | D1: FATHER NAME | E1: MOTHER NAME | F1: GENDER | G1: ST.NO | H1: P.NO | I1: MAIL ID
A2: 1 | B2: 23VE1A6601 | C2: ADDAGUDURU MANAS | D2: ADDAGUDURU RAGHUVEER | E2: ADDAGUDURU SADHVI | F2: Male | G2: 7799766622 | H2: 8801905090 | I2: manasaddaguduru@gmail.com
A3: 2 | B3: 23VE1A6602 | C3: ALUKA ASMITHA REDDY | D3: ALUKA VENKAT REDDY | E3: ALUKA SHIRISHA | F3: Female | G3: 9390865951 | H3: 9346889032 | I3: alukaasmithareddy@gmail.com
A4: 3 | B4: 23VE1A6603 | C4: AVULA NIKITHA | D4: AVULA VENKATA REDDY | E4: AVULA PRASANNA | F4: Female | G4: 8374944503 | H4: 9704527171 | I4: avulanikitha1104@gmail.com
A5: 4 | B5: 23VE1A6604 | C5: B HARSHITH REDDY | D5: B LOHITH REDDY | E5: B SUJATHA | F5: Male | G5: 8555938259 | H5: 8340998312 | I5: harshithreddy1416@gmail.com
A6: 5 | B6: 23VE1A6605 | C6: BAIRAGOUNI TEJASVI | D6: BAIRAGOUNI VENKATESH GOUD | E6: BAIRAGOUNI KALPANA | F6: Female | G6: 8919605652 | H6: 9246444735 | I6: tejasvigoud19@gmail.com
A7: 6 | B7: 23VE1A6606 | C7: BAIREDDY BHAVITHA | D7: BAIREDDY JAGAN MOHAN REDDY | E7: BAIREDDY ARUNA | F7: Female | G7: 9000384847 | H7: 9490499799 | I7: bhavithabaireddy92@gmail.com
A8: 7 | B8: 23VE1A6607 | C8: BANTUPALLY BHASKAR | D8: B SATHYAM | E8: B ESHWARAMMA | F8: Male | G8: 6305581431 | H8: 6303078431 | I8: bhaskarbantupally@gmail.com
A9: 8 | B9: 23VE1A6608 | C9: BIJJULA RISHIKA | D9: BIJJULA DHARMENDER REDDY | E9: BIJJULA KAVITHA | F9: Female | G9: 6301374308 | H9: 9032151836 | I9: rishikabijjulareddy@gmail.com
A10: 9 | B10: 23VE1A6609 | C10: BOJARABOINI RACHANA | D10: BOJARABOINI JAGADISH | E10: BOJARABOINI SANTOSHNEETA | F10: Female | G10: 7702061737 | H10: 9849446643 | I10: rachanamudhiraj1@gmail.com
A11: 10 | B11: 23VE1A6610 | C11: CH ANIL GOUD | D11: CH KASHANNA | E11: CH JYOTHI | F11: Male | G11: 8309892470 | H11: 9640882465 | I11: lovelyanil300@gmail.com
A12: 11 | B12: 23VE1A6611 | C12: CHEGANTI SHIVA CHARAN | D12: CHEGANTI BALARAJU | E12: CHEGANTI MANGAMMA | F12: Male | G12: 8008296938 | H12: 9959932122 | I12: shmudhiraj@gmail.com
A13: 12 | B13: 23VE1A6612 | C13: DHARAVATH RAKESH | D13: DHARAVATH VENKANNA | E13: DHARAVATH VIJAYA KUMARI | F13: Male | G13: 9063125223 | H13: 9010163826 | I13: dharavathrakesh115@gmail.com
... A67: 66 | B67: 24VE5A6602 | C67: MALTUMKAR GANESH | D67: MALTUMKAR BALAJI | E67: MALTUMKAR SUSHEELA | F67: Male | G67: 9346197482 | H67: 7013452956 | I67: ganesh101104@gmail.com
A68: 67 | B68: 24VE5A6603 | C68: RAVULA LOKESH | D68: RAVULA VENKANNA | F68: Male
A69: 68 | B69: 24VE5A6604 | C69: VAJHALA SAINANDU | D69: VAJHALA NAGENDRA PRASAD | E69: VAJHALA SARADA | F69: Male | G69: 7207006151 | H69: 9963693760 | I69: vajhalasainandu@gmail.com
A70: 69 | B70: 24VE5A6605 | C70: VALUROUTHU KARTHIKEYA | D70: VALUROUTHU SRIDHARA RAO | E70: VOLUROUTHU RAJESHWARI | F70: Male | G70: 9515310727 | H70: 9390278570 | I70: karthik5363945@gmail.com

Sheet 4-1B
